{"nick":"gibson042","reason":"Quit: Leaving.","date":"2018-11-24T01:10:31.961Z","type":"quit"}
{"nick":"devsnek","message":"is HostPromiseRejectionTracker supposed to be used in test262 to detect the failure of async tests?","date":"2018-11-24T04:41:43.789Z","type":"message"}
{"nick":"devsnek","message":"it isn't mentioned in interpreting.md but it doesn't seem like there is any other way.","date":"2018-11-24T04:42:35.112Z","type":"message"}
{"nick":"jmdyck","reason":"Remote host closed the connection","date":"2018-11-24T05:45:50.535Z","type":"quit"}
{"nick":"Bakkot","message":"devsnek: I just use a timeout, as INTERPRETING.md suggests: \"The implementation is free to select an appropriate length of time to wait before considering the test \"timed out\" and failing.\"","date":"2018-11-24T05:48:31.444Z","type":"message"}
{"nick":"jmdyck","date":"2018-11-24T12:50:36.429Z","type":"join"}
{"nick":"devsnek","message":"Bakkot: I ended up adding a timeout but you still have to track promises to actually get the error","date":"2018-11-24T15:58:46.521Z","type":"message"}
{"nick":"devsnek","message":"so after the timeout if there is a rejected promise, fail the test with the value of the promise","date":"2018-11-24T15:59:16.224Z","type":"message"}
{"nick":"devsnek","message":"built-ins/Function/prototype/name.js seems to be a misinterpretation of the spec","date":"2018-11-24T21:22:52.017Z","type":"message"}
{"nick":"devsnek","message":"oh wait Function.prototype is another function","date":"2018-11-24T21:23:17.396Z","type":"message"}
{"nick":"devsnek","message":"that tricks me every time","date":"2018-11-24T21:23:20.422Z","type":"message"}
